2023-12-17 18:09:28,899 - ERROR - main: 46 - HTTPConnectionPool(host='127.0.0.1', port=8000): Max retries exceeded with url: /screen/ (Caused by NewConnectionError('<urllib3.connection.HTTPConnection object at 0x000001B396D9A850>: Failed to establish a new connection: [WinError 10061] Подключение не установлено, т.к. конечный компьютер отверг запрос на подключение'))
Traceback (most recent call last):
  File "D:\Dev\Freelance\Project-deposite\venv\Lib\site-packages\urllib3\connection.py", line 174, in _new_conn
    conn = connection.create_connection(
           ^^^^^^^^^^^^^^^^^^^^^^^^^^^^^
  File "D:\Dev\Freelance\Project-deposite\venv\Lib\site-packages\urllib3\util\connection.py", line 95, in create_connection
    raise err
  File "D:\Dev\Freelance\Project-deposite\venv\Lib\site-packages\urllib3\util\connection.py", line 85, in create_connection
    sock.connect(sa)
ConnectionRefusedError: [WinError 10061] Подключение не установлено, т.к. конечный компьютер отверг запрос на подключение

During handling of the above exception, another exception occurred:

Traceback (most recent call last):
  File "D:\Dev\Freelance\Project-deposite\venv\Lib\site-packages\urllib3\connectionpool.py", line 714, in urlopen
    httplib_response = self._make_request(
                       ^^^^^^^^^^^^^^^^^^^
  File "D:\Dev\Freelance\Project-deposite\venv\Lib\site-packages\urllib3\connectionpool.py", line 415, in _make_request
    conn.request(method, url, **httplib_request_kw)
  File "D:\Dev\Freelance\Project-deposite\venv\Lib\site-packages\urllib3\connection.py", line 244, in request
    super(HTTPConnection, self).request(method, url, body=body, headers=headers)
  File "C:\Users\user\AppData\Local\Programs\Python\Python311\Lib\http\client.py", line 1286, in request
    self._send_request(method, url, body, headers, encode_chunked)
  File "C:\Users\user\AppData\Local\Programs\Python\Python311\Lib\http\client.py", line 1332, in _send_request
    self.endheaders(body, encode_chunked=encode_chunked)
  File "C:\Users\user\AppData\Local\Programs\Python\Python311\Lib\http\client.py", line 1281, in endheaders
    self._send_output(message_body, encode_chunked=encode_chunked)
  File "C:\Users\user\AppData\Local\Programs\Python\Python311\Lib\http\client.py", line 1041, in _send_output
    self.send(msg)
  File "C:\Users\user\AppData\Local\Programs\Python\Python311\Lib\http\client.py", line 979, in send
    self.connect()
  File "D:\Dev\Freelance\Project-deposite\venv\Lib\site-packages\urllib3\connection.py", line 205, in connect
    conn = self._new_conn()
           ^^^^^^^^^^^^^^^^
  File "D:\Dev\Freelance\Project-deposite\venv\Lib\site-packages\urllib3\connection.py", line 186, in _new_conn
    raise NewConnectionError(
urllib3.exceptions.NewConnectionError: <urllib3.connection.HTTPConnection object at 0x000001B396D9A850>: Failed to establish a new connection: [WinError 10061] Подключение не установлено, т.к. конечный компьютер отверг запрос на подключение

During handling of the above exception, another exception occurred:

Traceback (most recent call last):
  File "D:\Dev\Freelance\Project-deposite\venv\Lib\site-packages\requests\adapters.py", line 486, in send
    resp = conn.urlopen(
           ^^^^^^^^^^^^^
  File "D:\Dev\Freelance\Project-deposite\venv\Lib\site-packages\urllib3\connectionpool.py", line 798, in urlopen
    retries = retries.increment(
              ^^^^^^^^^^^^^^^^^^
  File "D:\Dev\Freelance\Project-deposite\venv\Lib\site-packages\urllib3\util\retry.py", line 592, in increment
    raise MaxRetryError(_pool, url, error or ResponseError(cause))
urllib3.exceptions.MaxRetryError: HTTPConnectionPool(host='127.0.0.1', port=8000): Max retries exceeded with url: /screen/ (Caused by NewConnectionError('<urllib3.connection.HTTPConnection object at 0x000001B396D9A850>: Failed to establish a new connection: [WinError 10061] Подключение не установлено, т.к. конечный компьютер отверг запрос на подключение'))

During handling of the above exception, another exception occurred:

Traceback (most recent call last):
  File "D:\Dev\Freelance\Project-deposite\ftp\ftp_sender_fake.py", line 31, in main
    response = requests.post(ENDPOINT, data={'name': file.name, 'worker': WORKER}, files=screen, timeout=10)
               ^^^^^^^^^^^^^^^^^^^^^^^^^^^^^^^^^^^^^^^^^^^^^^^^^^^^^^^^^^^^^^^^^^^^^^^^^^^^^^^^^^^^^^^^^^^^^
  File "D:\Dev\Freelance\Project-deposite\venv\Lib\site-packages\requests\api.py", line 115, in post
    return request("post", url, data=data, json=json, **kwargs)
           ^^^^^^^^^^^^^^^^^^^^^^^^^^^^^^^^^^^^^^^^^^^^^^^^^^^^
  File "D:\Dev\Freelance\Project-deposite\venv\Lib\site-packages\requests\api.py", line 59, in request
    return session.request(method=method, url=url, **kwargs)
           ^^^^^^^^^^^^^^^^^^^^^^^^^^^^^^^^^^^^^^^^^^^^^^^^^
  File "D:\Dev\Freelance\Project-deposite\venv\Lib\site-packages\requests\sessions.py", line 589, in request
    resp = self.send(prep, **send_kwargs)
           ^^^^^^^^^^^^^^^^^^^^^^^^^^^^^^
  File "D:\Dev\Freelance\Project-deposite\venv\Lib\site-packages\requests\sessions.py", line 703, in send
    r = adapter.send(request, **kwargs)
        ^^^^^^^^^^^^^^^^^^^^^^^^^^^^^^^
  File "D:\Dev\Freelance\Project-deposite\venv\Lib\site-packages\requests\adapters.py", line 519, in send
    raise ConnectionError(e, request=request)
requests.exceptions.ConnectionError: HTTPConnectionPool(host='127.0.0.1', port=8000): Max retries exceeded with url: /screen/ (Caused by NewConnectionError('<urllib3.connection.HTTPConnection object at 0x000001B396D9A850>: Failed to establish a new connection: [WinError 10061] Подключение не установлено, т.к. конечный компьютер отверг запрос на подключение'))
